Traceback (most recent call last):
  File "/opt/hostedtoolcache/Python/3.11.13/x64/lib/python3.11/site-packages/jupyter_core/utils/__init__.py", line 154, in wrapped
    asyncio.get_running_loop()
RuntimeError: no running event loop

During handling of the above exception, another exception occurred:

Traceback (most recent call last):
  File "/opt/hostedtoolcache/Python/3.11.13/x64/lib/python3.11/site-packages/jupyter_cache/executors/utils.py", line 58, in single_nb_execution
    executenb(
  File "/opt/hostedtoolcache/Python/3.11.13/x64/lib/python3.11/site-packages/nbclient/client.py", line 1319, in execute
    return NotebookClient(nb=nb, resources=resources, km=km, **kwargs).execute()
           ^^^^^^^^^^^^^^^^^^^^^^^^^^^^^^^^^^^^^^^^^^^^^^^^^^^^^^^^^^^^^^^^^^^^^
  File "/opt/hostedtoolcache/Python/3.11.13/x64/lib/python3.11/site-packages/jupyter_core/utils/__init__.py", line 158, in wrapped
    return loop.run_until_complete(inner)
           ^^^^^^^^^^^^^^^^^^^^^^^^^^^^^^
  File "/opt/hostedtoolcache/Python/3.11.13/x64/lib/python3.11/asyncio/base_events.py", line 654, in run_until_complete
    return future.result()
           ^^^^^^^^^^^^^^^
  File "/opt/hostedtoolcache/Python/3.11.13/x64/lib/python3.11/site-packages/nbclient/client.py", line 709, in async_execute
    await self.async_execute_cell(
  File "/opt/hostedtoolcache/Python/3.11.13/x64/lib/python3.11/site-packages/nbclient/client.py", line 1062, in async_execute_cell
    await self._check_raise_for_error(cell, cell_index, exec_reply)
  File "/opt/hostedtoolcache/Python/3.11.13/x64/lib/python3.11/site-packages/nbclient/client.py", line 918, in _check_raise_for_error
    raise CellExecutionError.from_cell_and_msg(cell, exec_reply_content)
nbclient.exceptions.CellExecutionError: An error occurred while executing the following cell:
------------------
from sqlalchemy import create_engine
import pandas as pd

my_creds = []
with open('/courses/PHYS7332.202610/shared/student_mysql_credentials.txt', 'r') as f:
    for line in f.readlines():
        my_creds.append(line.strip())

hostname="mysql-0005"
dbname="PHYS7332"
uname=my_creds[0]
pwd=my_creds[1]

engine = create_engine("mysql+pymysql://{user}:{pw}@{host}/{db}"
                           .format(host=hostname, db=dbname,
                                   user=uname,pw=pwd))

------------------


[31m---------------------------------------------------------------------------[39m
[31mFileNotFoundError[39m                         Traceback (most recent call last)
[36mCell[39m[36m [39m[32mIn[1][39m[32m, line 5[39m
[32m      2[39m [38;5;28;01mimport[39;00m[38;5;250m [39m[34;01mpandas[39;00m[38;5;250m [39m[38;5;28;01mas[39;00m[38;5;250m [39m[34;01mpd[39;00m
[32m      4[39m my_creds = []
[32m----> [39m[32m5[39m [38;5;28;01mwith[39;00m [38;5;28;43mopen[39;49m[43m([49m[33;43m'[39;49m[33;43m/courses/PHYS7332.202610/shared/student_mysql_credentials.txt[39;49m[33;43m'[39;49m[43m,[49m[43m [49m[33;43m'[39;49m[33;43mr[39;49m[33;43m'[39;49m[43m)[49m [38;5;28;01mas[39;00m f:
[32m      6[39m     [38;5;28;01mfor[39;00m line [38;5;129;01min[39;00m f.readlines():
[32m      7[39m         my_creds.append(line.strip())

[36mFile [39m[32m/opt/hostedtoolcache/Python/3.11.13/x64/lib/python3.11/site-packages/IPython/core/interactiveshell.py:343[39m, in [36m_modified_open[39m[34m(file, *args, **kwargs)[39m
[32m    336[39m [38;5;28;01mif[39;00m file [38;5;129;01min[39;00m {[32m0[39m, [32m1[39m, [32m2[39m}:
[32m    337[39m     [38;5;28;01mraise[39;00m [38;5;167;01mValueError[39;00m(
[32m    338[39m         [33mf[39m[33m"[39m[33mIPython won[39m[33m'[39m[33mt let you open fd=[39m[38;5;132;01m{[39;00mfile[38;5;132;01m}[39;00m[33m by default [39m[33m"[39m
[32m    339[39m         [33m"[39m[33mas it is likely to crash IPython. If you know what you are doing, [39m[33m"[39m
[32m    340[39m         [33m"[39m[33myou can use builtins[39m[33m'[39m[33m open.[39m[33m"[39m
[32m    341[39m     )
[32m--> [39m[32m343[39m [38;5;28;01mreturn[39;00m [43mio_open[49m[43m([49m[43mfile[49m[43m,[49m[43m [49m[43m*[49m[43margs[49m[43m,[49m[43m [49m[43m*[49m[43m*[49m[43mkwargs[49m[43m)[49m

[31mFileNotFoundError[39m: [Errno 2] No such file or directory: '/courses/PHYS7332.202610/shared/student_mysql_credentials.txt'

